2024-12-25 22:42:13,973 ERROR: Exception on / [GET] [in /home/equist/.local/lib/python3.12/site-packages/flask/app.py:1414]
Traceback (most recent call last):
  File "/home/equist/.local/lib/python3.12/site-packages/sqlalchemy/engine/base.py", line 1967, in _exec_single_context
    self.dialect.do_execute(
  File "/home/equist/.local/lib/python3.12/site-packages/sqlalchemy/engine/default.py", line 941, in do_execute
    cursor.execute(statement, parameters)
sqlite3.OperationalError: no such table: user

The above exception was the direct cause of the following exception:

Traceback (most recent call last):
  File "/home/equist/.local/lib/python3.12/site-packages/flask/app.py", line 2190, in wsgi_app
    response = self.full_dispatch_request()
               ^^^^^^^^^^^^^^^^^^^^^^^^^^^^
  File "/home/equist/.local/lib/python3.12/site-packages/flask/app.py", line 1486, in full_dispatch_request
    rv = self.handle_user_exception(e)
         ^^^^^^^^^^^^^^^^^^^^^^^^^^^^^
  File "/home/equist/.local/lib/python3.12/site-packages/flask/app.py", line 1482, in full_dispatch_request
    rv = self.preprocess_request()
         ^^^^^^^^^^^^^^^^^^^^^^^^^
  File "/home/equist/.local/lib/python3.12/site-packages/flask/app.py", line 1974, in preprocess_request
    rv = self.ensure_sync(before_func)()
         ^^^^^^^^^^^^^^^^^^^^^^^^^^^^^^^
  File "/home/equist/Programming/ports-game/ports/src/routes.py", line 79, in before_request
    if current_user.is_authenticated:
       ^^^^^^^^^^^^^^^^^^^^^^^^^^^^^
  File "/home/equist/.local/lib/python3.12/site-packages/werkzeug/local.py", line 318, in __get__
    obj = instance._get_current_object()
          ^^^^^^^^^^^^^^^^^^^^^^^^^^^^^^
  File "/home/equist/.local/lib/python3.12/site-packages/werkzeug/local.py", line 526, in _get_current_object
    return get_name(local())
                    ^^^^^^^
  File "/home/equist/.local/lib/python3.12/site-packages/flask_login/utils.py", line 25, in <lambda>
    current_user = LocalProxy(lambda: _get_user())
                                      ^^^^^^^^^^^
  File "/home/equist/.local/lib/python3.12/site-packages/flask_login/utils.py", line 370, in _get_user
    current_app.login_manager._load_user()
  File "/home/equist/.local/lib/python3.12/site-packages/flask_login/login_manager.py", line 376, in _load_user
    user = self._load_user_from_remember_cookie(cookie)
           ^^^^^^^^^^^^^^^^^^^^^^^^^^^^^^^^^^^^^^^^^^^^
  File "/home/equist/.local/lib/python3.12/site-packages/flask_login/login_manager.py", line 420, in _load_user_from_remember_cookie
    user = self._user_callback(user_id)
           ^^^^^^^^^^^^^^^^^^^^^^^^^^^^
  File "/home/equist/Programming/ports-game/ports/src/models.py", line 85, in load_user
    return db.session.get(User, int(id))
           ^^^^^^^^^^^^^^^^^^^^^^^^^^^^^
  File "/home/equist/.local/lib/python3.12/site-packages/sqlalchemy/orm/scoping.py", line 1060, in get
    return self._proxied.get(
           ^^^^^^^^^^^^^^^^^^
  File "/home/equist/.local/lib/python3.12/site-packages/sqlalchemy/orm/session.py", line 3693, in get
    return self._get_impl(
           ^^^^^^^^^^^^^^^
  File "/home/equist/.local/lib/python3.12/site-packages/sqlalchemy/orm/session.py", line 3873, in _get_impl
    return db_load_fn(
           ^^^^^^^^^^^
  File "/home/equist/.local/lib/python3.12/site-packages/sqlalchemy/orm/loading.py", line 694, in load_on_pk_identity
    session.execute(
  File "/home/equist/.local/lib/python3.12/site-packages/sqlalchemy/orm/session.py", line 2362, in execute
    return self._execute_internal(
           ^^^^^^^^^^^^^^^^^^^^^^^
  File "/home/equist/.local/lib/python3.12/site-packages/sqlalchemy/orm/session.py", line 2247, in _execute_internal
    result: Result[Any] = compile_state_cls.orm_execute_statement(
                          ^^^^^^^^^^^^^^^^^^^^^^^^^^^^^^^^^^^^^^^^
  File "/home/equist/.local/lib/python3.12/site-packages/sqlalchemy/orm/context.py", line 305, in orm_execute_statement
    result = conn.execute(
             ^^^^^^^^^^^^^
  File "/home/equist/.local/lib/python3.12/site-packages/sqlalchemy/engine/base.py", line 1418, in execute
    return meth(
           ^^^^^
  File "/home/equist/.local/lib/python3.12/site-packages/sqlalchemy/sql/elements.py", line 515, in _execute_on_connection
    return connection._execute_clauseelement(
           ^^^^^^^^^^^^^^^^^^^^^^^^^^^^^^^^^^
  File "/home/equist/.local/lib/python3.12/site-packages/sqlalchemy/engine/base.py", line 1640, in _execute_clauseelement
    ret = self._execute_context(
          ^^^^^^^^^^^^^^^^^^^^^^
  File "/home/equist/.local/lib/python3.12/site-packages/sqlalchemy/engine/base.py", line 1846, in _execute_context
    return self._exec_single_context(
           ^^^^^^^^^^^^^^^^^^^^^^^^^^
  File "/home/equist/.local/lib/python3.12/site-packages/sqlalchemy/engine/base.py", line 1986, in _exec_single_context
    self._handle_dbapi_exception(
  File "/home/equist/.local/lib/python3.12/site-packages/sqlalchemy/engine/base.py", line 2355, in _handle_dbapi_exception
    raise sqlalchemy_exception.with_traceback(exc_info[2]) from e
  File "/home/equist/.local/lib/python3.12/site-packages/sqlalchemy/engine/base.py", line 1967, in _exec_single_context
    self.dialect.do_execute(
  File "/home/equist/.local/lib/python3.12/site-packages/sqlalchemy/engine/default.py", line 941, in do_execute
    cursor.execute(statement, parameters)
sqlalchemy.exc.OperationalError: (sqlite3.OperationalError) no such table: user
[SQL: SELECT user.id AS user_id, user.username AS user_username, user.email AS user_email, user.password_hash AS user_password_hash, user.about_me AS user_about_me, user.last_seen AS user_last_seen 
FROM user 
WHERE user.id = ?]
[parameters: (5,)]
(Background on this error at: https://sqlalche.me/e/20/e3q8)
2024-12-25 22:43:26,939 INFO: Ports game [in /home/equist/Programming/ports-game/ports/src/__init__.py:31]
2024-12-25 22:43:56,982 INFO: Ports game [in /home/equist/Programming/ports-game/ports/src/__init__.py:31]
2024-12-25 22:44:49,332 INFO: Ports game [in /home/equist/Programming/ports-game/ports/src/__init__.py:31]
2024-12-25 22:45:06,479 INFO: Ports game [in /home/equist/Programming/ports-game/ports/src/__init__.py:31]
2024-12-25 22:46:48,745 INFO: Ports game [in /home/equist/Programming/ports-game/ports/src/__init__.py:31]
2024-12-25 22:46:57,513 INFO: Ports game [in /home/equist/Programming/ports-game/ports/src/__init__.py:31]
2024-12-26 21:43:29,327 INFO: Ports game [in /home/equist/Programming/ports-game/ports/src/__init__.py:31]
2024-12-26 21:45:15,575 INFO: Ports game [in /home/equist/Programming/ports-game/ports/src/__init__.py:31]
2024-12-26 21:45:21,856 ERROR: Exception on / [GET] [in /home/equist/Programming/ports-game/ports/lib/python3.12/site-packages/flask/app.py:838]
Traceback (most recent call last):
  File "/home/equist/Programming/ports-game/ports/lib/python3.12/site-packages/flask/app.py", line 1473, in wsgi_app
    response = self.full_dispatch_request()
               ^^^^^^^^^^^^^^^^^^^^^^^^^^^^
  File "/home/equist/Programming/ports-game/ports/lib/python3.12/site-packages/flask/app.py", line 882, in full_dispatch_request
    rv = self.handle_user_exception(e)
         ^^^^^^^^^^^^^^^^^^^^^^^^^^^^^
  File "/home/equist/Programming/ports-game/ports/lib/python3.12/site-packages/flask/app.py", line 880, in full_dispatch_request
    rv = self.dispatch_request()
         ^^^^^^^^^^^^^^^^^^^^^^^
  File "/home/equist/Programming/ports-game/ports/lib/python3.12/site-packages/flask/app.py", line 865, in dispatch_request
    return self.ensure_sync(self.view_functions[rule.endpoint])(**view_args)  # type: ignore[no-any-return]
           ^^^^^^^^^^^^^^^^^^^^^^^^^^^^^^^^^^^^^^^^^^^^^^^^^^^^^^^^^^^^^^^^^
  File "/home/equist/Programming/ports-game/ports/lib/python3.12/site-packages/flask_login/utils.py", line 290, in decorated_view
    return current_app.ensure_sync(func)(*args, **kwargs)
           ^^^^^^^^^^^^^^^^^^^^^^^^^^^^^^^^^^^^^^^^^^^^^^
  File "/home/equist/Programming/ports-game/ports/src/routes.py", line 28, in index
    return render_template('index.html', title='Home', posts=posts)
           ^^^^^^^^^^^^^^^^^^^^^^^^^^^^^^^^^^^^^^^^^^^^^^^^^^^^^^^^
  File "/home/equist/Programming/ports-game/ports/lib/python3.12/site-packages/flask/templating.py", line 150, in render_template
    return _render(app, template, context)
           ^^^^^^^^^^^^^^^^^^^^^^^^^^^^^^^
  File "/home/equist/Programming/ports-game/ports/lib/python3.12/site-packages/flask/templating.py", line 131, in _render
    rv = template.render(context)
         ^^^^^^^^^^^^^^^^^^^^^^^^
  File "/home/equist/Programming/ports-game/ports/lib/python3.12/site-packages/jinja2/environment.py", line 1304, in render
    self.environment.handle_exception()
  File "/home/equist/Programming/ports-game/ports/lib/python3.12/site-packages/jinja2/environment.py", line 939, in handle_exception
    raise rewrite_traceback_stack(source=source)
  File "/home/equist/Programming/ports-game/ports/src/templates/index.html", line 1, in top-level template code
    {% extends "base.html" %}
  File "/home/equist/Programming/ports-game/ports/lib/python3.12/site-packages/jinja2/environment.py", line 939, in handle_exception
    raise rewrite_traceback_stack(source=source)
  File "/home/equist/Programming/ports-game/ports/src/templates/base.html", line 37, in template
    {% endif %}
jinja2.exceptions.TemplateSyntaxError: Encountered unknown tag 'endif'.
2024-12-26 21:45:32,633 INFO: Ports game [in /home/equist/Programming/ports-game/ports/src/__init__.py:31]
2024-12-26 23:05:07,777 INFO: Ports game [in /home/equist/Programming/ports-game/ports/src/__init__.py:31]
